UNCAUGHT EXCEPTION:
Traceback (most recent call last):
  File "/home/stef/devel/uweb3/uweb3/__init__.py", line 239, in get_response
    raise Exception()
Exception
UNCAUGHT EXCEPTION:
Traceback (most recent call last):
  File "/home/stef/devel/uweb3/uweb3/__init__.py", line 239, in get_response
    raise Exception()
Exception
UNCAUGHT EXCEPTION:
Traceback (most recent call last):
  File "/home/stef/devel/uweb3/uweb3/__init__.py", line 239, in get_response
    raise Exception()
Exception
UNCAUGHT EXCEPTION:
Traceback (most recent call last):
  File "/home/stef/devel/uweb3/uweb3/__init__.py", line 239, in get_response
    raise
RuntimeError: No active exception to reraise
UNCAUGHT EXCEPTION:
Traceback (most recent call last):
  File "/home/stef/devel/uweb3/uweb3/__init__.py", line 239, in get_response
    raise
RuntimeError: No active exception to reraise
UNCAUGHT EXCEPTION:
Traceback (most recent call last):
  File "/home/stef/devel/uweb3/uweb3/__init__.py", line 239, in get_response
    raise
RuntimeError: No active exception to reraise
UNCAUGHT EXCEPTION:
Traceback (most recent call last):
  File "/home/stef/devel/uweb3/uweb3/__init__.py", line 240, in get_response
    raise Exception()
Exception
UNCAUGHT EXCEPTION:
Traceback (most recent call last):
  File "/home/stef/devel/uweb3/uweb3/__init__.py", line 240, in get_response
    raise Exception()
Exception
UNCAUGHT EXCEPTION:
Traceback (most recent call last):
  File "/home/stef/devel/uweb3/uweb3/__init__.py", line 240, in get_response
    raise Exception()
Exception
UNCAUGHT EXCEPTION:
Traceback (most recent call last):
  File "/home/stef/devel/uweb3/uweb3/__init__.py", line 240, in get_response
    raise Exception()
Exception
UNCAUGHT EXCEPTION:
Traceback (most recent call last):
  File "/home/stef/devel/uweb3/uweb3/__init__.py", line 240, in get_response
    raise Exception()
Exception
UNCAUGHT EXCEPTION:
Traceback (most recent call last):
  File "/home/stef/devel/uweb3/uweb3/__init__.py", line 240, in get_response
    raise Exception()
Exception
UNCAUGHT EXCEPTION:
Traceback (most recent call last):
  File "/home/stef/devel/uweb3/uweb3/__init__.py", line 240, in get_response
    raise Exception()
Exception
UNCAUGHT EXCEPTION:
Traceback (most recent call last):
  File "/home/stef/devel/uweb3/uweb3/__init__.py", line 240, in get_response
    raise Exception()
Exception
UNCAUGHT EXCEPTION:
Traceback (most recent call last):
  File "/home/stef/devel/uweb3/uweb3/__init__.py", line 240, in get_response
    raise Exception()
Exception
UNCAUGHT EXCEPTION:
Traceback (most recent call last):
  File "/home/stef/devel/uweb3/uweb3/__init__.py", line 240, in get_response
    raise Exception()
Exception
UNCAUGHT EXCEPTION:
Traceback (most recent call last):
  File "/home/stef/devel/uweb3/uweb3/__init__.py", line 240, in get_response
    raise Exception()
Exception
UNCAUGHT EXCEPTION:
Traceback (most recent call last):
  File "/home/stef/devel/uweb3/uweb3/__init__.py", line 240, in get_response
    raise Exception()
Exception
UNCAUGHT EXCEPTION:
Traceback (most recent call last):
  File "/home/stef/devel/uweb3/uweb3/__init__.py", line 240, in get_response
    raise Exception()
Exception
UNCAUGHT EXCEPTION:
Traceback (most recent call last):
  File "/home/stef/devel/uweb3/uweb3/__init__.py", line 240, in get_response
    raise Exception()
Exception
UNCAUGHT EXCEPTION:
Traceback (most recent call last):
  File "/home/stef/devel/uweb3/uweb3/__init__.py", line 240, in get_response
    raise Exception()
Exception
UNCAUGHT EXCEPTION:
Traceback (most recent call last):
  File "/home/stef/devel/uweb3/uweb3/__init__.py", line 240, in get_response
    raise Exception()
Exception
UNCAUGHT EXCEPTION:
Traceback (most recent call last):
  File "/home/stef/devel/uweb3/uweb3/__init__.py", line 240, in get_response
    raise Exception()
Exception
UNCAUGHT EXCEPTION:
Traceback (most recent call last):
  File "/home/stef/devel/uweb3/uweb3/__init__.py", line 240, in get_response
    raise Exception()
Exception
UNCAUGHT EXCEPTION:
Traceback (most recent call last):
  File "/home/stef/devel/uweb3/uweb3/__init__.py", line 240, in get_response
    raise Exception()
Exception
UNCAUGHT EXCEPTION:
Traceback (most recent call last):
  File "/home/stef/devel/uweb3/uweb3/__init__.py", line 240, in get_response
    raise Exception()
Exception
UNCAUGHT EXCEPTION:
Traceback (most recent call last):
  File "/home/stef/devel/uweb3/uweb3/__init__.py", line 240, in get_response
    raise Exception()
Exception
